<?xml version="1.0" encoding="utf-8"?>
<!-- This URDF was automatically created by SolidWorks to URDF Exporter! Originally created by Stephen Brawner (brawner@gmail.com) 
     Commit Version: 1.6.0-1-g15f4949  Build Version: 1.6.7594.29634
     For more information, please see http://wiki.ros.org/sw_urdf_exporter -->
<robot
  name="lily_urdf">
 
  <material name="black">
    <color rgba="0.0 0.0 0.0 1.0"/>
  </material>
  <material name="blue">
    <color rgba="0.203125 0.23828125 0.28515625 1.0"/>
  </material>
  <material name="green">
    <color rgba="0.0 0.8 0.0 1.0"/>
  </material>
  <material name="grey">
    <color rgba="0.2 0.2 0.2 1.0"/>
  </material>
  <material name="orange">
    <color rgba="1.0 0.423529411765 0.0392156862745 1.0"/>
  </material>
  <material name="brown">
    <color rgba="0.870588235294 0.811764705882 0.764705882353 1.0"/>
  </material>
  <material name="red">
    <color rgba="0.80078125 0.12890625 0.1328125 1.0"/>
  </material>
  <material name="white">
    <color rgba="1.0 1.0 1.0 1.0"/>
  </material>  
  <gazebo reference="base_link">
    <material>Gazebo/Orange</material>
  </gazebo>
  
  <link
    name="base_link">
    <inertial>
      <origin
        xyz="0.0148522592395787 -2.71766984982214E-05 0.0336562906951377"
        rpy="0 0 0" />
      <mass
        value="0.616327044012325" />
      <inertia
        ixx="0.000348573324198144"
        ixy="-1.14229155274189E-07"
        ixz="2.88395764354253E-05"
        iyy="0.000518121343710203"
        iyz="-4.33150431600376E-07"
        izz="0.000722721071788088" />
    </inertial>
    <visual>
      <origin
        xyz="0 0 0"
        rpy="0 0 0" />
      <geometry>
        <mesh
          filename="package://lily_urdf/meshes/base_link.STL" />
      </geometry>
      <material
        name="">
        <color
          rgba="0.498039215686275 0.498039215686275 0.498039215686275 1" />
      </material>
    </visual>
    <collision>
      <origin
        xyz="0 0 0"
        rpy="0 0 0" />
      <geometry>
        <mesh
          filename="package://lily_urdf/meshes/base_link.STL" />
      </geometry>
    </collision>
  </link>
  <link
    name="r_wheel">
    <inertial>
      <origin
        xyz="-4.16333634234434E-17 0.0053336743072566 3.46944695195361E-17"
        rpy="0 0 0" />
      <mass
        value="0.0761855462810734" />
      <inertia
        ixx="2.88213458730614E-05"
        ixy="-6.86678077736033E-22"
        ixz="-8.55695725466241E-23"
        iyy="5.03899285691294E-05"
        iyz="7.41115563258836E-22"
        izz="2.88213458730614E-05" />
    </inertial>
    <visual>
      <origin
        xyz="0 0 0"
        rpy="0 0 0" />
      <geometry>
        <mesh
          filename="package://lily_urdf/meshes/r_wheel.STL" />
      </geometry>
      <material
        name="">
        <color
          rgba="1 1 1 0.32" />
      </material>
    </visual>
    <collision>
      <origin
        xyz="0 0 0"
        rpy="0 0 0" />
      <geometry>
        <mesh
          filename="package://lily_urdf/meshes/r_wheel.STL" />
      </geometry>
    </collision>
  </link>
  <joint
    name="right_wheel"
    type="continuous">
    <origin
      xyz="-0.035749 -0.094 -0.037"
      rpy="0 0 0" />
    <parent
      link="base_link" />
    <child
      link="r_wheel" />
    <axis
      xyz="0 -1 0" />
    <limit
      effort="1"
      velocity="1" />
  </joint>
  <link
    name="l_wheel">
    <inertial>
      <origin
        xyz="0 -0.00533367430725661 4.16333634234434E-17"
        rpy="0 0 0" />
      <mass
        value="0.0761855462810734" />
      <inertia
        ixx="2.88213458730614E-05"
        ixy="-1.9877552667949E-22"
        ixz="1.0060907317603E-21"
        iyy="5.03899285691294E-05"
        iyz="-1.31387564671363E-21"
        izz="2.88213458730614E-05" />
    </inertial>
    <visual>
      <origin
        xyz="0 0 0"
        rpy="0 0 0" />
      <geometry>
        <mesh
          filename="package://lily_urdf/meshes/l_wheel.STL" />
      </geometry>
      <material
        name="">
        <color
          rgba="1 1 1 0.32" />
      </material>
    </visual>
    <collision>
      <origin
        xyz="0 0 0"
        rpy="0 0 0" />
      <geometry>
        <mesh
          filename="package://lily_urdf/meshes/l_wheel.STL" />
      </geometry>
    </collision>
  </link>
  <joint
    name="left_wheel"
    type="continuous">
    <origin
      xyz="-0.035749 0.094 -0.037"            -0.035749 -0.094 -0.037
      rpy="0 0 0" />
    <parent
      link="base_link" />
    <child
      link="l_wheel" />
    <axis
      xyz="0 1 0" />
    <limit
      effort="1"
      velocity="1" />
  </joint>
  
  <gazebo>
    <plugin name="differential_drive_controller" filename="libgazebo_ros_diff_drive.so">
        <alwaysOn>true</alwaysOn>
        <updateRate>100</updateRate>
        <legacyMode>false</legacyMode>
        <leftJoint>left_wheel</leftJoint>
        <rightJoint>right_wheel</rightJoint>
        <wheelSeparation>0.25</wheelSeparation>
        <wheelDiameter>0.07</wheelDiameter>
        <torque>5</torque>
        <commandTopic>cmd_vel</commandTopic>
        <odometryTopic>odom</odometryTopic>
        <odometryFrame>odom</odometryFrame>
        <robotBaseFrame>base_link</robotBaseFrame>
        <publishWheelTF>false</publishWheelTF>
        <publishWheelJointState>false</publishWheelJointState>
        <rosDebugLevel>na</rosDebugLevel>
        <wheelAcceleration>0</wheelAcceleration>
        <wheelTorque>5</wheelTorque>
        <odometrySource>world</odometrySource>
        <publishTf>1</publishTf>
        <publishOdomTF>true</publishOdomTF>
        
    </plugin>
</gazebo> 




  
</robot>
